{
 "PRed": [
  {
   "PR": {
    "number": 11,
    "state": "closed"
   },
   "data": {
    "bot_rerun": false,
    "migrator_name": "Version",
    "migrator_version": 0,
    "version": "0.0.4"
   },
   "keys": [
    "bot_rerun",
    "migrator_name",
    "migrator_version",
    "version"
   ]
  },
  {
   "PR": {
    "labels": [],
    "number": 29,
    "state": "closed"
   },
   "data": {
    "bot_rerun": false,
    "migrator_name": "Version",
    "migrator_version": 0,
    "version": "0.2.4"
   },
   "keys": [
    "bot_rerun",
    "migrator_name",
    "migrator_version",
    "version"
   ]
  },
  {
   "PR": {
    "labels": [],
    "number": 30,
    "state": "closed"
   },
   "data": {
    "bot_rerun": false,
    "migrator_name": "Version",
    "migrator_version": 0,
    "version": "0.2.5"
   },
   "keys": [
    "bot_rerun",
    "migrator_name",
    "migrator_version",
    "version"
   ]
  },
  {
   "PR": {
    "labels": [],
    "number": 31,
    "state": "closed"
   },
   "data": {
    "bot_rerun": false,
    "migrator_name": "Version",
    "migrator_version": 0,
    "version": "0.2.6"
   },
   "keys": [
    "bot_rerun",
    "migrator_name",
    "migrator_version",
    "version"
   ]
  },
  {
   "PR": {
    "labels": [
     {
      "name": "automerge"
     }
    ],
    "number": 32,
    "state": "closed"
   },
   "data": {
    "bot_rerun": false,
    "migrator_name": "Version",
    "migrator_version": 0,
    "version": "0.2.7"
   },
   "keys": [
    "bot_rerun",
    "migrator_name",
    "migrator_version",
    "version"
   ]
  },
  {
   "PR": {
    "labels": [],
    "number": 33,
    "state": "closed"
   },
   "data": {
    "bot_rerun": false,
    "migrator_name": "Version",
    "migrator_version": 0,
    "version": "0.2.8"
   },
   "keys": [
    "bot_rerun",
    "migrator_name",
    "migrator_version",
    "version"
   ]
  },
  {
   "PR": {
    "head": {
     "ref": "<this_is_not_a_branch>"
    },
    "state": "closed"
   },
   "data": {
    "bot_rerun": false,
    "migrator_name": "Version",
    "migrator_version": 0,
    "version": "0.2.9"
   },
   "keys": [
    "bot_rerun",
    "migrator_name",
    "migrator_version",
    "version"
   ]
  },
  {
   "PR": {
    "labels": [],
    "number": 35,
    "state": "closed"
   },
   "data": {
    "bot_rerun": false,
    "migrator_name": "Version",
    "migrator_version": 0,
    "version": "0.2.10"
   },
   "keys": [
    "bot_rerun",
    "migrator_name",
    "migrator_version",
    "version"
   ]
  }
 ],
 "bad": {
  "exception": "<class 'requests.exceptions.ConnectionError'>: A connection-level exception occurred: ('Connection aborted.', RemoteDisconnected('Remote end closed connection without response'))",
  "traceback": [
   "Traceback (most recent call last):",
   "  File \"/home/runner/miniconda3/envs/cf-scripts/lib/python3.10/site-packages/urllib3/connectionpool.py\", line 715, in urlopen",
   "    httplib_response = self._make_request(",
   "  File \"/home/runner/miniconda3/envs/cf-scripts/lib/python3.10/site-packages/urllib3/connectionpool.py\", line 467, in _make_request",
   "    six.raise_from(e, None)",
   "  File \"<string>\", line 3, in raise_from",
   "  File \"/home/runner/miniconda3/envs/cf-scripts/lib/python3.10/site-packages/urllib3/connectionpool.py\", line 462, in _make_request",
   "    httplib_response = conn.getresponse()",
   "  File \"/home/runner/miniconda3/envs/cf-scripts/lib/python3.10/http/client.py\", line 1375, in getresponse",
   "    response.begin()",
   "  File \"/home/runner/miniconda3/envs/cf-scripts/lib/python3.10/http/client.py\", line 318, in begin",
   "    version, status, reason = self._read_status()",
   "  File \"/home/runner/miniconda3/envs/cf-scripts/lib/python3.10/http/client.py\", line 287, in _read_status",
   "    raise RemoteDisconnected(\"Remote end closed connection without\"",
   "http.client.RemoteDisconnected: Remote end closed connection without response",
   "",
   "During handling of the above exception, another exception occurred:",
   "",
   "Traceback (most recent call last):",
   "  File \"/home/runner/miniconda3/envs/cf-scripts/lib/python3.10/site-packages/requests/adapters.py\", line 486, in send",
   "    resp = conn.urlopen(",
   "  File \"/home/runner/miniconda3/envs/cf-scripts/lib/python3.10/site-packages/urllib3/connectionpool.py\", line 799, in urlopen",
   "    retries = retries.increment(",
   "  File \"/home/runner/miniconda3/envs/cf-scripts/lib/python3.10/site-packages/urllib3/util/retry.py\", line 550, in increment",
   "    raise six.reraise(type(error), error, _stacktrace)",
   "  File \"/home/runner/miniconda3/envs/cf-scripts/lib/python3.10/site-packages/urllib3/packages/six.py\", line 769, in reraise",
   "    raise value.with_traceback(tb)",
   "  File \"/home/runner/miniconda3/envs/cf-scripts/lib/python3.10/site-packages/urllib3/connectionpool.py\", line 715, in urlopen",
   "    httplib_response = self._make_request(",
   "  File \"/home/runner/miniconda3/envs/cf-scripts/lib/python3.10/site-packages/urllib3/connectionpool.py\", line 467, in _make_request",
   "    six.raise_from(e, None)",
   "  File \"<string>\", line 3, in raise_from",
   "  File \"/home/runner/miniconda3/envs/cf-scripts/lib/python3.10/site-packages/urllib3/connectionpool.py\", line 462, in _make_request",
   "    httplib_response = conn.getresponse()",
   "  File \"/home/runner/miniconda3/envs/cf-scripts/lib/python3.10/http/client.py\", line 1375, in getresponse",
   "    response.begin()",
   "  File \"/home/runner/miniconda3/envs/cf-scripts/lib/python3.10/http/client.py\", line 318, in begin",
   "    version, status, reason = self._read_status()",
   "  File \"/home/runner/miniconda3/envs/cf-scripts/lib/python3.10/http/client.py\", line 287, in _read_status",
   "    raise RemoteDisconnected(\"Remote end closed connection without\"",
   "urllib3.exceptions.ProtocolError: ('Connection aborted.', RemoteDisconnected('Remote end closed connection without response'))",
   "",
   "During handling of the above exception, another exception occurred:",
   "",
   "Traceback (most recent call last):",
   "  File \"/home/runner/miniconda3/envs/cf-scripts/lib/python3.10/site-packages/github3/models.py\", line 201, in _request",
   "    return request_method(*args, **kwargs)",
   "  File \"/home/runner/miniconda3/envs/cf-scripts/lib/python3.10/site-packages/requests/sessions.py\", line 637, in post",
   "    return self.request(\"POST\", url, data=data, json=json, **kwargs)",
   "  File \"/home/runner/miniconda3/envs/cf-scripts/lib/python3.10/site-packages/github3/session.py\", line 171, in request",
   "    response = super().request(*args, **kwargs)",
   "  File \"/home/runner/miniconda3/envs/cf-scripts/lib/python3.10/site-packages/requests/sessions.py\", line 589, in request",
   "    resp = self.send(prep, **send_kwargs)",
   "  File \"/home/runner/miniconda3/envs/cf-scripts/lib/python3.10/site-packages/requests/sessions.py\", line 703, in send",
   "    r = adapter.send(request, **kwargs)",
   "  File \"/home/runner/miniconda3/envs/cf-scripts/lib/python3.10/site-packages/requests/adapters.py\", line 501, in send",
   "    raise ConnectionError(err, request=request)",
   "requests.exceptions.ConnectionError: ('Connection aborted.', RemoteDisconnected('Remote end closed connection without response'))",
   "",
   "During handling of the above exception, another exception occurred:",
   "",
   "Traceback (most recent call last):",
   "  File \"/home/runner/work/cf-scripts/cf-scripts/cf-scripts/conda_forge_tick/auto_tick.py\", line 1270, in _run_migrator",
   "    migrator_uid, pr_json = run(",
   "  File \"/home/runner/work/cf-scripts/cf-scripts/cf-scripts/conda_forge_tick/auto_tick.py\", line 424, in run",
   "    pr_json = push_repo(",
   "  File \"/home/runner/work/cf-scripts/cf-scripts/cf-scripts/conda_forge_tick/git_utils.py\", line 658, in push_repo",
   "    pr = repo.create_pull(title, base_branch, head, body=body)",
   "  File \"/home/runner/miniconda3/envs/cf-scripts/lib/python3.10/site-packages/github3/decorators.py\", line 24, in auth_wrapper",
   "    return func(self, *args, **kwargs)",
   "  File \"/home/runner/miniconda3/envs/cf-scripts/lib/python3.10/site-packages/github3/repos/repo.py\", line 1185, in create_pull",
   "    return self._create_pull(data)",
   "  File \"/home/runner/miniconda3/envs/cf-scripts/lib/python3.10/site-packages/github3/repos/repo.py\", line 117, in _create_pull",
   "    json = self._json(self._post(url, data=data), 201)",
   "  File \"/home/runner/miniconda3/envs/cf-scripts/lib/python3.10/site-packages/github3/models.py\", line 226, in _post",
   "    return self._request(\"post\", url, data, **kwargs)",
   "  File \"/home/runner/miniconda3/envs/cf-scripts/lib/python3.10/site-packages/github3/models.py\", line 206, in _request",
   "    raise exceptions.ConnectionError(exc)",
   "github3.exceptions.ConnectionError: <class 'requests.exceptions.ConnectionError'>: A connection-level exception occurred: ('Connection aborted.', RemoteDisconnected('Remote end closed connection without response'))",
   ""
  ]
 },
 "pinning_version": "2023.12.09.07.23.46",
 "pre_pr_migrator_attempts": {
  "version": 1
 },
 "pre_pr_migrator_status": {
  "version": "bot error (<a href=\"https://github.com/regro/cf-scripts/actions/runs/7403104873\">bot CI job</a>): main: Traceback (most recent call last):\n  File \"/home/runner/miniconda3/envs/cf-scripts/lib/python3.10/site-packages/urllib3/connectionpool.py\", line 715, in urlopen\n    httplib_response = self._make_request(\n  File \"/home/runner/miniconda3/envs/cf-scripts/lib/python3.10/site-packages/urllib3/connectionpool.py\", line 467, in _make_request\n    six.raise_from(e, None)\n  File \"<string>\", line 3, in raise_from\n  File \"/home/runner/miniconda3/envs/cf-scripts/lib/python3.10/site-packages/urllib3/connectionpool.py\", line 462, in _make_request\n    httplib_response = conn.getresponse()\n  File \"/home/runner/miniconda3/envs/cf-scripts/lib/python3.10/http/client.py\", line 1375, in getresponse\n    response.begin()\n  File \"/home/runner/miniconda3/envs/cf-scripts/lib/python3.10/http/client.py\", line 318, in begin\n    version, status, reason = self._read_status()\n  File \"/home/runner/miniconda3/envs/cf-scripts/lib/python3.10/http/client.py\", line 287, in _read_status\n    raise RemoteDisconnected(\"Remote end closed connection without\"\nhttp.client.RemoteDisconnected: Remote end closed connection without response\n\nDuring handling of the above exception, another exception occurred:\n\nTraceback (most recent call last):\n  File \"/home/runner/miniconda3/envs/cf-scripts/lib/python3.10/site-packages/requests/adapters.py\", line 486, in send\n    resp = conn.urlopen(\n  File \"/home/runner/miniconda3/envs/cf-scripts/lib/python3.10/site-packages/urllib3/connectionpool.py\", line 799, in urlopen\n    retries = retries.increment(\n  File \"/home/runner/miniconda3/envs/cf-scripts/lib/python3.10/site-packages/urllib3/util/retry.py\", line 550, in increment\n    raise six.reraise(type(error), error, _stacktrace)\n  File \"/home/runner/miniconda3/envs/cf-scripts/lib/python3.10/site-packages/urllib3/packages/six.py\", line 769, in reraise\n    raise value.with_traceback(tb)\n  File \"/home/runner/miniconda3/envs/cf-scripts/lib/python3.10/site-packages/urllib3/connectionpool.py\", line 715, in urlopen\n    httplib_response = self._make_request(\n  File \"/home/runner/miniconda3/envs/cf-scripts/lib/python3.10/site-packages/urllib3/connectionpool.py\", line 467, in _make_request\n    six.raise_from(e, None)\n  File \"<string>\", line 3, in raise_from\n  File \"/home/runner/miniconda3/envs/cf-scripts/lib/python3.10/site-packages/urllib3/connectionpool.py\", line 462, in _make_request\n    httplib_response = conn.getresponse()\n  File \"/home/runner/miniconda3/envs/cf-scripts/lib/python3.10/http/client.py\", line 1375, in getresponse\n    response.begin()\n  File \"/home/runner/miniconda3/envs/cf-scripts/lib/python3.10/http/client.py\", line 318, in begin\n    version, status, reason = self._read_status()\n  File \"/home/runner/miniconda3/envs/cf-scripts/lib/python3.10/http/client.py\", line 287, in _read_status\n    raise RemoteDisconnected(\"Remote end closed connection without\"\nurllib3.exceptions.ProtocolError: ('Connection aborted.', RemoteDisconnected('Remote end closed connection without response'))\n\nDuring handling of the above exception, another exception occurred:\n\nTraceback (most recent call last):\n  File \"/home/runner/miniconda3/envs/cf-scripts/lib/python3.10/site-packages/github3/models.py\", line 201, in _request\n    return request_method(*args, **kwargs)\n  File \"/home/runner/miniconda3/envs/cf-scripts/lib/python3.10/site-packages/requests/sessions.py\", line 637, in post\n    return self.request(\"POST\", url, data=data, json=json, **kwargs)\n  File \"/home/runner/miniconda3/envs/cf-scripts/lib/python3.10/site-packages/github3/session.py\", line 171, in request\n    response = super().request(*args, **kwargs)\n  File \"/home/runner/miniconda3/envs/cf-scripts/lib/python3.10/site-packages/requests/sessions.py\", line 589, in request\n    resp = self.send(prep, **send_kwargs)\n  File \"/home/runner/miniconda3/envs/cf-scripts/lib/python3.10/site-packages/requests/sessions.py\", line 703, in send\n    r = adapter.send(request, **kwargs)\n  File \"/home/runner/miniconda3/envs/cf-scripts/lib/python3.10/site-packages/requests/adapters.py\", line 501, in send\n    raise ConnectionError(err, request=request)\nrequests.exceptions.ConnectionError: ('Connection aborted.', RemoteDisconnected('Remote end closed connection without response'))\n\nDuring handling of the above exception, another exception occurred:\n\nTraceback (most recent call last):\n  File \"/home/runner/work/cf-scripts/cf-scripts/cf-scripts/conda_forge_tick/auto_tick.py\", line 1270, in _run_migrator\n    migrator_uid, pr_json = run(\n  File \"/home/runner/work/cf-scripts/cf-scripts/cf-scripts/conda_forge_tick/auto_tick.py\", line 424, in run\n    pr_json = push_repo(\n  File \"/home/runner/work/cf-scripts/cf-scripts/cf-scripts/conda_forge_tick/git_utils.py\", line 658, in push_repo\n    pr = repo.create_pull(title, base_branch, head, body=body)\n  File \"/home/runner/miniconda3/envs/cf-scripts/lib/python3.10/site-packages/github3/decorators.py\", line 24, in auth_wrapper\n    return func(self, *args, **kwargs)\n  File \"/home/runner/miniconda3/envs/cf-scripts/lib/python3.10/site-packages/github3/repos/repo.py\", line 1185, in create_pull\n    return self._create_pull(data)\n  File \"/home/runner/miniconda3/envs/cf-scripts/lib/python3.10/site-packages/github3/repos/repo.py\", line 117, in _create_pull\n    json = self._json(self._post(url, data=data), 201)\n  File \"/home/runner/miniconda3/envs/cf-scripts/lib/python3.10/site-packages/github3/models.py\", line 226, in _post\n    return self._request(\"post\", url, data, **kwargs)\n  File \"/home/runner/miniconda3/envs/cf-scripts/lib/python3.10/site-packages/github3/models.py\", line 206, in _request\n    raise exceptions.ConnectionError(exc)\ngithub3.exceptions.ConnectionError: <class 'requests.exceptions.ConnectionError'>: A connection-level exception occurred: ('Connection aborted.', RemoteDisconnected('Remote end closed connection without response'))\n"
 },
 "smithy_version": "3.30.1"
}